Workbook

Sheet Baseline calculator
A1: Parameter | B1: Suggested value | C1: Unit | D1: Type | E1: Calculated from / dependencies | F1: Notes
A2: N0 | B2: 1000 | C2: patients / occupied beds | D2: Input assumption | E2: Chosen model scale | F2: 1,000 occupied acute beds is a large hospital/trust-scale model.
A3: effective_mean_LOS | B3: 7.5 | C3: days | D3: Input assumption | E3: Patient turnover assumption | F3: Used to derive adm_rate = N0 / effective_mean_LOS.
A4: model_time | B4: 365 | C4: days | D4: Run setting input | E4: QMD Section 4 | F4: Use longer runs for burn-in/equilibrium checks.
A5: time_step | B5: 0.5 | C5: days | D5: Run setting input | E5: QMD Section 4 | F5: Half-day output step is compatible with daily rates.
A6: UKHSA_HO_rate_per_100k_beddays | B6: 23.3 | C6: cases / 100,000 bed-days | D6: Calibration input | E6: UKHSA 2024/25 hospital-onset CDI rate | F6: Used to calculate the reported hospital-onset CDI target.
A7: UKHSA_CO_CDI_count | B7: 10540 | C7: cases/year | D7: Calibration input | E7: UKHSA 2024/25 community-onset CDI count | F7: Used only as a check on prop_adm_I.
A8: UKHSA_total_beddays | B8: 36195302 | C8: bed-days/year | D8: Calibration input | E8: UKHSA 2024/25 denominator | F8: Used only as a check on community-onset import scaling.
A9: prop_adm_C | B9: 0.086 | C9: proportion | D9: Input assumption | E9: Admission toxigenic colonisation prevalence | F9: Central value from admission carriage meta-analysis.
A10: prop_adm_I | B10: 0.002 | C10: proportion | D10: Input assumption | E10: Symptomatic/infected admissions | F10: Close to community-onset CDI import scaling when adm_rate is 133/day.
A11: isolate_before_test | B11: TRUE | C11: TRUE/FALSE | D11: Scenario control input | E11: make_mod_parms() argument | F11: Baseline assumes suspected cases are isolated before results.
A12: prop_I_suspected | B12: 1 | C12: proportion | D12: Scenario control input | E12: make_mod_parms() argument | F12: Use 0.5 in a missed-identification sensitivity scenario.
A13: test_sens | B13: 0.65 | C13: proportion | D13: Scenario control input | E13: make_mod_parms() argument | F13: Central value for toxin-positive clinical CDI detection; use ~0.90 for GDH/NAAT toxigenic detection.
A14: t_test_turnaround | B14: 1 | C14: days | D14: Scenario control input | E14: make_mod_parms() argument | F14: Central NHS lab-workflow assumption; scenario range 1-2 days.
A15: beta0 | B15: 0.0005 | C15: per day | D15: Input assumption / calibration parameter | E15: Fixed list in Parameters.R | F15: Background/environmental colonisation force; calibrate.
A16: betaC | B16: 0.008 | C16: per day | D16: Input assumption / calibration parameter | E16: Fixed list in Parameters.R | F16: Colonised-patient contribution to lambda; calibrate.
A17: betaI | B17: 0.04 | C17: per day | D17: Input assumption / calibration parameter | E17: Fixed list in Parameters.R | F17: Unisolated symptomatic-patient contribution; calibrate.
A18: betaXtreat | B18: 0.004 | C18: per day | D18: Input assumption / calibration parameter | E18: Fixed list in Parameters.R | F18: Isolated/treated contribution; lower than betaI.
A19: prop_progress_C_to_I | B19: 0.0655 | C19: proportion-like scaling | D19: Input assumption / calibration parameter | E19: Used in alpha formula | F19: Chosen so alpha is about 0.003/day with abx_prop=0.373, abx_mult=2, t_progress=30.
A20: abx_prop | B20: 0.373 | C20: proportion | D20: Input assumption | E20: Used in alpha formula | F20: England acute-care antibiotic prevalence from PPS.
A21: abx_mult | B21: 2 | C21: multiplier | D21: Input assumption | E21: Used in alpha formula | F21: Risk multiplier is class/case-mix dependent; retain as sensitivity parameter.
A22: t_progress_C_to_I | B22: 30 | C22: days | D22: Input assumption | E22: Used in alpha formula | F22: Time window for cumulative progression risk; prevents alpha from being too large.
A23: prop_decolonise_C_to_S | B23: 0.05 | C23: proportion | D23: Input assumption | E23: Used in mu formula | F23: Weakly evidenced; retain current value and sensitivity-test.
... A36: mortXtreat_mult | B36: 25 | C36: multiplier | D36: Input assumption / calibration parameter | E36: Fixed list in Parameters.R | F36: Suggested to calibrate CDI-related deaths; can be lower than mortI_mult if treatment reduces mortality.
A37: target_HO_CDI_per_year | B37: =$B$6/100000*$B$2*365 -> 85.045 | C37: cases/year | D37: Calculated | E37: UKHSA_HO_rate_per_100k_beddays, N0 | F37: Reported hospital-onset CDI target for this model scale.
A38: target_HO_CDI_per_day | B38: =$B$37/365 -> 0.233 | C38: cases/day | D38: Calculated | E38: target_HO_CDI_per_year | F38: Daily target for calibration of alpha/betas/confirmed cases.
A39: target_CO_CDI_imports_per_year | B39: =$B$7/$B$8*$B$2*365 -> 106.28727 | C39: cases/year | D39: Calculated | E39: UKHSA_CO_CDI_count, UKHSA_total_beddays, N0 | F39: Approximate community-onset import target scaled to N0.
A40: target_prop_adm_I_from_CO | B40: =$B$39/($B$41*365) -> 0.0021839851 | C40: proportion | D40: Calculated | E40: target_CO_CDI_imports_per_year, adm_rate | F40: Check on prop_adm_I.
A41: adm_rate | B41: =$B$2/$B$3 -> 133.33333 | C41: admissions/day | D41: Calculated | E41: N0, effective_mean_LOS | F41: Total admission flow into the model.
A42: admS | B42: =$B$41*(1-$B$9-$B$10) -> 121.6 | C42: patients/day | D42: Runtime calculated | E42: adm_rate, prop_adm_C, prop_adm_I | F42: Susceptible admissions in Model1A_ODE().
A43: admC | B43: =$B$41*$B$9 -> 11.466667 | C43: patients/day | D43: Runtime calculated | E43: adm_rate, prop_adm_C | F43: Colonised admissions in Model1A_ODE().
A44: admI | B44: =$B$41*$B$10 -> 0.26666667 | C44: patients/day | D44: Runtime calculated | E44: adm_rate, prop_adm_I | F44: Infected admissions in Model1A_ODE().
A45: betaFN | B45: =$B$17 -> 0.04 | C45: per day | D45: Calculated | E45: betaI | F45: False negatives transmit like unisolated symptomatic infected cases.
A46: betaXtest | B46: =IF($B$11,$B$18,$B$17) -> 0.004 | C46: per day | D46: Calculated | E46: isolate_before_test, betaXtreat, betaI | F46: Suspected cases transmit like Xtreat if isolated before test; otherwise like I.
A47: alpha | B47: =$B$19*((1-$B$20)+($B$20*$B$21))/$B$22 -> 0.0029977167 | C47: per day | D47: Calculated | E47: prop_progress_C_to_I, abx_prop, abx_mult, t_progress_C_to_I | F47: C -> I progression rate.
A48: mu | B48: =$B$23/$B$24 -> 0.01 | C48: per day | D48: Calculated | E48: prop_decolonise_C_to_S, t_decolonise_C_to_S | F48: C -> S decolonisation rate.
A49: delta | B49: =$B$33/($B$29+$B$30) -> 0.055172414 | C49: per day | D49: Calculated | E49: prop_Xtreat_to_S, losXtreat, t_patient_transfer | F49: Xtreat -> S recovery/return rate.
A50: disS | B50: =1/($B$25+$B$30) -> 0.13333333 | C50: per day | D50: Calculated | E50: losS, t_patient_transfer | F50: S discharge rate.
A51: disC | B51: =1/($B$26+$B$30) -> 0.13333333 | C51: per day | D51: Calculated | E51: losC, t_patient_transfer | F51: C discharge rate.
A52: disI | B52: =1/($B$27+$B$30) -> 0.068965517 | C52: per day | D52: Calculated | E52: losI, t_patient_transfer | F52: I discharge rate.
...

Sheet Parameter table
A1: Group | B1: Parameter | C1: Input/calculated in current code | D1: Script where set or calculated | E1: Model role | F1: Current value in uploaded files | G1: Suggested central value | H1: Unit | I1: Plausible range / scenarios | J1: Determined by / dependencies | K1: Formula / encoding | L1: Reasoning | M1: Source URLs | N1: Confidence
A2: Scale / settings | B2: N0 | C2: Input assumption; not explicit as single variable | D2: QMD Section 5 via S0+C0+I0+Xtest0+FN0+Xtreat0 | E2: Initial living hospital census | F2: 1000 implied by initial states | G2: ='Baseline calculator'!$B$2 -> 1000 | H2: patients | I2: Scale to local occupied acute beds | J2: Chosen model scale | K2: Set initial states to sum to N0 | L2: Use occupied acute beds as the model scale; a 1,000-bed model is about a large acute hospital/trust scale. | M2: https://www.gov.uk/government/statistics/mrsa-mssa-and-e-coli-bacteraemia-and-c-difficile-infection-annual-epidemiological-commentary/annual-epidemiological-commentary-gram-negative-mrsa-mssa-bacteraemia-and-c-difficile-infections-up-to-and-including-financial-year-2024-to-2025; https://www.nuffieldtrust.org.uk/resource/hospital-bed-occupancy; Uploaded Model1_ODE_Model_Run.qmd | N2: High for scaling
A3: Scale / settings | B3: model_time | C3: Input assumption | D3: Model1_ODE_Model_Run.qmd Section 4 | E3: Simulation duration | F3: 365 | G3: ='Baseline calculator'!$B$4 -> 365 | H3: days | I3: 365-3650 | J3: User/model run design | K3: run_settings$model_time | L3: One year aligns with annual CDI targets; longer runs are useful for burn-in. | M3: Uploaded Model1_ODE_Model_Run.qmd; Uploaded README.md | N3: High
A4: Scale / settings | B4: time_step | C4: Input assumption | D4: Model1_ODE_Model_Run.qmd Section 4 | E4: ODE output time step | F4: 0.5 | G4: ='Baseline calculator'!$B$5 -> 0.5 | H4: days | I4: 0.25-1 | J4: User/model run design | K4: run_settings$time_step | L4: Half-day outputs are suitable for daily rates and 1-day testing assumptions. | M4: Uploaded Model1_ODE_Model_Run.qmd; Uploaded README.md | N4: High
A5: Initial conditions | B5: S0 | C5: Input set directly in current code; suggested value calculated | D5: QMD Section 5 | E5: Susceptible patients at t=0 | F5: 870 | G5: ='Baseline calculator'!$B$72 -> 909.44068 | H5: patients | I5: Residual after C0/I0/Xtest0/FN0/Xtreat0 | J5: N0, C0, I0, Xtest0, FN0, Xtreat0 | K5: S0 = N0 - C0 - I0 - Xtest0 - FN0 - Xtreat0 | L5: Make S0 the residual so living states sum exactly to N0. | M5: Uploaded Model1_ODE_Model_Run.qmd; https://link.springer.com/article/10.1186/s13099-024-00674-0; https://www.gov.uk/government/statistics/mrsa-mssa-and-e-coli-bacteraemia-and-c-difficile-infection-annual-epidemiological-commentary/annual-epidemiological-commentary-gram-negative-mrsa-mssa-bacteraemia-and-c-difficile-infections-up-to-and-including-financial-year-2024-to-2025 | N5: Medium
A6: Initial conditions | B6: C0 | C6: Input set directly in current code; suggested value calculated | D6: QMD Section 5 | E6: Colonised patients at t=0 | F6: 120 | G6: ='Baseline calculator'!$B$66 -> 86 | H6: patients | I6: 50-125 per 1000 | J6: N0, prop_adm_C | K6: C0 = N0 * prop_adm_C | L6: Toxigenic colonisation at admission is a reasonable starting prevalence proxy. | M6: https://link.springer.com/article/10.1186/s13099-024-00674-0 | N6: Medium-high
A7: Initial conditions | B7: I0 | C7: Input set directly in current code; suggested value calculated | D7: QMD Section 5 | E7: Symptomatic infected, not yet suspected | F7: 10 | G7: ='Baseline calculator'!$B$67 -> 0.5825 | H7: patients | I7: 0.5-3 per 1000 | J7: target_HO_CDI_per_day, gamma | K7: I0 approx target_HO_CDI_per_day / gamma | L7: Reported hospital-onset CDI rate implies a small unrecognised symptomatic pool if suspected cases are identified within about 2 days. | M7: https://www.gov.uk/government/statistics/mrsa-mssa-and-e-coli-bacteraemia-and-c-difficile-infection-annual-epidemiological-commentary/annual-epidemiological-commentary-gram-negative-mrsa-mssa-bacteraemia-and-c-difficile-infections-up-to-and-including-financial-year-2024-to-2025; Uploaded Model1_ODE_Parameters.R | N7: Medium
A8: Initial conditions | B8: Xtest0 | C8: Input set directly in current code; suggested value calculated | D8: QMD Section 5 | E8: Suspected cases awaiting result | F8: 0 | G8: ='Baseline calculator'!$B$68 -> 0.35846154 | H8: patients | I8: 0-1.5 per 1000 | J8: target_HO_CDI_per_day, theta | K8: Xtest0 approx target_HO_CDI_per_day / theta | L8: Small non-zero initial value avoids early artificial delay; after burn-in it matters little. | M8: https://www.ouh.nhs.uk/microbiology/a-z/c-difficile/; Uploaded Model1_ODE_Parameters.R | N8: Low-medium
A9: Initial conditions | B9: FN0 | C9: Input set directly in current code; suggested value calculated | D9: QMD Section 5 | E9: False negatives awaiting retest | F9: 0 | G9: ='Baseline calculator'!$B$69 -> 0.40627671 | H9: patients | I9: 0-1 per 1000 | J9: pi, Xtest0, sigma, disFN, mortFN | K9: FN0 approx (pi * Xtest0) / (sigma + disFN + mortFN) | L9: Only meaningful when test_sens < 1; zero is acceptable for burn-in runs. | M9: https://www.gov.uk/government/publications/clostridioides-difficile-diagnostic-test-accuracy; https://www.ouh.nhs.uk/microbiology/a-z/c-difficile/; Uploaded Model1_ODE_Parameters.R | N9: Low
A10: Initial conditions | B10: Xtreat0 | C10: Input set directly in current code; suggested value calculated | D10: QMD Section 5 | E10: Confirmed isolated/on treatment | F10: 0 | G10: ='Baseline calculator'!$B$70 -> 3.2120771 | H10: patients | I10: 2-6 per 1000 | J10: target_HO_CDI_per_day, delta, disXtreat, mortXtreat | K10: Xtreat0 approx target_HO_CDI_per_day / (delta + disXtreat + mortXtreat) | L10: Uses reported HO-CDI incidence and the model's exits from Xtreat to initialise near steady occupancy. | M10: https://www.gov.uk/government/statistics/mrsa-mssa-and-e-coli-bacteraemia-and-c-difficile-infection-annual-epidemiological-commentary/annual-epidemiological-commentary-gram-negative-mrsa-mssa-bacteraemia-and-c-difficile-infections-up-to-and-including-financial-year-2024-to-2025; https://www.nice.org.uk/guidance/ng199/chapter/Recommendations; Uploaded Model1_ODE_Parameters.R | N10: Medium
A11: Initial conditions | B11: D0 | C11: Input assumption | D11: QMD Section 5 | E11: Cumulative deaths | F11: 0 | G11: ='Baseline calculator'!$B$71 -> 0 | H11: deaths | I11: 0 | J11: None | K11: D0 = 0 | L11: Cumulative absorbing count should start at zero unless continuing a prior run. | M11: Uploaded Model1_ODE_Model_Run.qmd | N11: High
A12: Admissions | B12: adm_rate | C12: Calculated suggested value; currently input fixed | D12: Parameters.R fixed list; suggested from N0/effective_mean_LOS | E12: Total admissions per day | F12: 1000/day | G12: ='Baseline calculator'!$B$41 -> 133.33333 | H12: admissions/day | I12: 100-200/day for mean LOS 10-5 days | J12: N0, effective_mean_LOS | K12: adm_rate = N0 / effective_mean_LOS | L12: For this ODE scale, admissions should be tied to census and effective LOS rather than total annual finished episodes. | M12: https://www.england.nhs.uk/statistics/statistical-work-areas/bed-availability-and-occupancy/; https://digital.nhs.uk/data-and-information/publications/statistical/hospital-admitted-patient-care-activity/2024-25; https://www.health.org.uk/reports-and-analysis/briefings/longer-hospital-stays-and-fewer-admissions; https://www.england.nhs.uk/long-read/the-model-acute-pathway-standards-for-care-of-acutely-unwell-patients-in-their-first-72-hours-in-hospital/; Uploaded Model1_ODE_Parameters.R | N12: Medium-high
A13: Admissions | B13: prop_adm_C | C13: Input assumption | D13: Parameters.R fixed list | E13: Proportion of admissions colonised | F13: 0.11 | G13: ='Baseline calculator'!$B$9 -> 0.086 | H13: proportion | I13: 0.05-0.125 | J13: External admission colonisation prevalence | K13: admC = adm_rate * prop_adm_C | L13: Admission toxigenic carriage around 8-9% is a defensible baseline, with high heterogeneity. | M13: https://link.springer.com/article/10.1186/s13099-024-00674-0 | N13: Medium-high
A14: Admissions | B14: prop_adm_I | C14: Input assumption | D14: Parameters.R fixed list | E14: Proportion of admissions infected/symptomatic | F14: 0.002 | G14: ='Baseline calculator'!$B$10 -> 0.002 | H14: proportion | I14: 0.0005-0.003 | J14: Community-onset CDI import target, adm_rate | K14: admI = adm_rate * prop_adm_I | L14: At 133 admissions/day, 0.002 gives about 97 infected admissions/year per 1,000 beds, close to community-onset CDI scaling. | M14: https://www.gov.uk/government/statistics/mrsa-mssa-and-e-coli-bacteraemia-and-c-difficile-infection-annual-epidemiological-commentary/annual-epidemiological-commentary-gram-negative-mrsa-mssa-bacteraemia-and-c-difficile-infections-up-to-and-including-financial-year-2024-to-2025 | N14: Medium
A15: Admissions | B15: admS | C15: Runtime calculated | D15: Functions.R Model1A_ODE() | E15: Susceptible admissions per day | F15: Calculated at runtime | G15: ='Baseline calculator'!$B$42 -> 121.6 | H15: patients/day | I15: Depends on adm_rate and admission prevalence | J15: adm_rate, prop_adm_C, prop_adm_I | K15: admS = adm_rate * (1 - prop_adm_C - prop_adm_I) | L15: Useful check that admission compartments sum to adm_rate. | M15: Uploaded Model1_ODE_Functions.R; Uploaded Model1_ODE_Parameters.R | N15: Formula
A16: Admissions | B16: admC | C16: Runtime calculated | D16: Functions.R Model1A_ODE() | E16: Colonised admissions per day | F16: Calculated at runtime | G16: ='Baseline calculator'!$B$43 -> 11.466667 | H16: patients/day | I16: Depends on adm_rate and prop_adm_C | J16: adm_rate, prop_adm_C | K16: admC = adm_rate * prop_adm_C | L16: Derived flow into C. | M16: Uploaded Model1_ODE_Functions.R; Uploaded Model1_ODE_Parameters.R | N16: Formula
A17: Admissions | B17: admI | C17: Runtime calculated | D17: Functions.R Model1A_ODE() | E17: Infected admissions per day | F17: Calculated at runtime | G17: ='Baseline calculator'!$B$44 -> 0.26666667 | H17: patients/day | I17: Depends on adm_rate and prop_adm_I | J17: adm_rate, prop_adm_I | K17: admI = adm_rate * prop_adm_I | L17: Derived flow into I. | M17: Uploaded Model1_ODE_Functions.R; Uploaded Model1_ODE_Parameters.R | N17: Formula
A18: Scenario controls | B18: isolate_before_test | C18: Scenario control input | D18: make_mod_parms() argument in Parameters.R; values set in QMD Section 3 | E18: Whether suspected cases are isolated before result | F18: TRUE in S1-S4 | G18: ='Baseline calculator'!$B$11 -> TRUE | H18: TRUE/FALSE | I18: TRUE/FALSE | J18: Scenario design | K18: Passed to make_mod_parms() | L18: This drives betaXtest, gamma, theta, pi and sigma formulas. | M18: Uploaded Model1_ODE_Model_Run.qmd; Uploaded Model1_ODE_Parameters.R | N18: High
A19: Scenario controls | B19: prop_I_suspected | C19: Scenario control input | D19: make_mod_parms() argument in Parameters.R; values set in QMD Section 3 | E19: Proportion of infected patients identified as suspected | F19: 1.0 in S1/S2; 0.5 in S3/S4 | G19: ='Baseline calculator'!$B$12 -> 1 | H19: proportion | I19: 0.5-1.0 | J19: Scenario design | K19: Used in gamma and gamma0 | L19: Keep as a scenario control for missed untested cases. | M19: Uploaded Model1_ODE_Model_Run.qmd; Uploaded Model1_ODE_Parameters.R | N19: Scenario assumption
A20: Scenario controls | B20: test_sens | C20: Scenario control input | D20: make_mod_parms() argument in Parameters.R; values set in QMD Section 3 | E20: Diagnostic sensitivity | F20: 1.0 in S1/S3; 0.5 in S2/S4 | G20: ='Baseline calculator'!$B$13 -> 0.65 | H20: proportion | I20: 0.55-0.82 toxin-positive pathway; 0.86-0.96 GDH/NAAT toxigenic detection | J20: Diagnostic test/algorithm choice | K20: Used in theta and pi | L20: Use lower values for toxin-positive clinical CDI detection; higher values for GDH/NAAT toxigenic detection. | M20: https://www.gov.uk/government/publications/clostridioides-difficile-diagnostic-test-accuracy | N20: Medium-high
A21: Scenario controls | B21: t_test_turnaround | C21: Scenario control input | D21: make_mod_parms() argument in Parameters.R; values set in QMD Section 3 | E21: Days from test to result/transfer logic | F21: 2 | G21: ='Baseline calculator'!$B$14 -> 1 | H21: days | I21: 1-2 days | J21: Lab workflow | K21: Used in theta and pi | L21: One day is a reasonable central operational value; retain 2 days as slower-turnaround scenario. | M21: https://www.ouh.nhs.uk/microbiology/a-z/c-difficile/; https://www.leedsth.nhs.uk/services/pathology/tests/clostridium-difficile-gdh-toxin-testing/ | N21: Medium
A22: Transmission | B22: beta0 | C22: Input assumption / calibration parameter | D22: Parameters.R fixed list | E22: Background/environmental colonisation force | F22: 0.30/day | G22: ='Baseline calculator'!$B$15 -> 0.0005 | H22: per day | I22: 0.0001-0.002 | J22: Calibration to HO-CDI/colonisation targets | K22: lambda includes beta0 directly | L22: Current beta0 alone implies hundreds of colonisations/day for N0=1000; reduce and calibrate. | M22: https://www.gov.uk/government/statistics/mrsa-mssa-and-e-coli-bacteraemia-and-c-difficile-infection-annual-epidemiological-commentary/annual-epidemiological-commentary-gram-negative-mrsa-mssa-bacteraemia-and-c-difficile-infections-up-to-and-including-financial-year-2024-to-2025; https://journals.plos.org/plosmedicine/article?id=10.1371/journal.pmed.1004712; https://www.cambridge.org/core/journals/infection-control-and-hospital-epidemiology/article/quantitative-summarization-of-hightouch-surfaces-and-epidemiological-parameters-of-clostridioides-difficile-acquisition-and-transmission-for-mathematical-modeling-a-systematic-review/CC98DD3B4DD7B5ACF7C07F9CC5476180; Uploaded Model1_ODE_Functions.R | N22: Low-medium
A23: Transmission | B23: betaC | C23: Input assumption / calibration parameter | D23: Parameters.R fixed list | E23: Colonised-patient contribution to lambda | F23: 0.50/day | G23: ='Baseline calculator'!$B$16 -> 0.008 | H23: per day | I23: 0.002-0.020 | J23: Calibration | K23: lambda contribution = betaC*C/N | L23: Not directly observable; calibrate with beta0 and betaI. | M23: https://journals.plos.org/plosmedicine/article?id=10.1371/journal.pmed.1004712; https://www.cambridge.org/core/journals/infection-control-and-hospital-epidemiology/article/quantitative-summarization-of-hightouch-surfaces-and-epidemiological-parameters-of-clostridioides-difficile-acquisition-and-transmission-for-mathematical-modeling-a-systematic-review/CC98DD3B4DD7B5ACF7C07F9CC5476180; Uploaded Model1_ODE_Functions.R | N23: Low
A24: Transmission | B24: betaI | C24: Input assumption / calibration parameter | D24: Parameters.R fixed list | E24: Unisolated symptomatic infected contribution to lambda | F24: 0.80/day | G24: ='Baseline calculator'!$B$17 -> 0.04 | H24: per day | I24: 0.010-0.080 | J24: Calibration | K24: lambda contribution = betaI*I/N; betaFN = betaI | L24: Use higher than betaC but much lower than current value for a 1,000-bed scale. | M24: https://journals.plos.org/plosmedicine/article?id=10.1371/journal.pmed.1004712; https://www.cambridge.org/core/journals/infection-control-and-hospital-epidemiology/article/quantitative-summarization-of-hightouch-surfaces-and-epidemiological-parameters-of-clostridioides-difficile-acquisition-and-transmission-for-mathematical-modeling-a-systematic-review/CC98DD3B4DD7B5ACF7C07F9CC5476180; Uploaded Model1_ODE_Functions.R | N24: Low
A25: Transmission | B25: betaXtreat | C25: Input assumption / calibration parameter | D25: Parameters.R fixed list | E25: Isolated/treated confirmed-case contribution to lambda | F25: 0.50/day | G25: ='Baseline calculator'!$B$18 -> 0.004 | H25: per day | I25: 0.001-0.010 | J25: Isolation/treatment effect assumption | K25: lambda contribution = betaXtreat*Xtreat/N | L25: Use lower than betaI to represent reduced onward exposure after isolation/treatment. | M25: https://journals.plos.org/plosmedicine/article?id=10.1371/journal.pmed.1004712; Uploaded Model1_ODE_Functions.R; Uploaded Model1_ODE_Parameters.R | N25: Low
A26: Transmission | B26: betaFN | C26: Calculated | D26: Parameters.R make_mod_parms() | E26: Transmission from false negatives | F26: betaI | G26: ='Baseline calculator'!$B$45 -> 0.04 | H26: per day | I26: Same as betaI unless behaviour changes | J26: betaI | K26: betaFN <- betaI | L26: False negatives are symptomatic and not isolated, so treating them like I is conceptually consistent. | M26: Uploaded Model1_ODE_Parameters.R | N26: Formula/model assumption
A27: Transmission | B27: betaXtest | C27: Calculated | D27: Parameters.R make_mod_parms() | E27: Transmission from suspected cases awaiting result | F27: betaXtreat if isolated; betaI otherwise | G27: ='Baseline calculator'!$B$46 -> 0.004 | H27: per day | I27: Scenario-dependent | J27: isolate_before_test, betaXtreat, betaI | K27: betaXtest <- if (isolate_before_test) betaXtreat else betaI | L27: This is a scenario mechanism rather than a biological input. | M27: Uploaded Model1_ODE_Parameters.R | N27: Formula/model assumption
A28: Transmission | B28: lambda | C28: Runtime calculated | D28: Functions.R Model1A_ODE() | E28: Force of colonisation | F28: Calculated at runtime | G28: See notes | H28: per day | I28: Calibrate to plausible colonisation and CDI incidence | J28: beta0, betaC, betaI, betaFN, betaXtest, betaXtreat, states, N | K28: lambda = beta0 + ((betaC*C + betaI*I + betaXtest*Xtest + betaFN*FN + betaXtreat*Xtreat)/N) | L28: This is the key beta calibration output; check day-0 and equilibrium values. | M28: Uploaded Model1_ODE_Functions.R; https://www.gov.uk/government/statistics/mrsa-mssa-and-e-coli-bacteraemia-and-c-difficile-infection-annual-epidemiological-commentary/annual-epidemiological-commentary-gram-negative-mrsa-mssa-bacteraemia-and-c-difficile-infections-up-to-and-including-financial-year-2024-to-2025; https://journals.plos.org/plosmedicine/article?id=10.1371/journal.pmed.1004712 | N28: Formula
A29: Progression | B29: prop_progress_C_to_I | C29: Input assumption / calibration parameter | D29: Parameters.R fixed list | E29: Progression scaling in alpha | F29: 0.50 | G29: ='Baseline calculator'!$B$19 -> 0.0655 | H29: proportion-like scaling | I29: 0.03-0.12 for reported HO-CDI calibration; up to ~0.218 for broader true CDI risk | J29: Target alpha, abx_prop, abx_mult, t_progress_C_to_I | K29: alpha = prop_progress_C_to_I*((1-abx_prop)+(abx_prop*abx_mult))/t_progress_C_to_I | L29: The current 0.50 over 5 days makes alpha far too high. Suggested value is calibrated so alpha is about 0.003/day. | M29: https://scholars.houstonmethodist.org/en/publications/colonization-with-toxinogenic-c-difficile-upon-hospital-admission/; https://www.gov.uk/government/statistics/mrsa-mssa-and-e-coli-bacteraemia-and-c-difficile-infection-annual-epidemiological-commentary/annual-epidemiological-commentary-gram-negative-mrsa-mssa-bacteraemia-and-c-difficile-infections-up-to-and-including-financial-year-2024-to-2025; Uploaded Model1_ODE_Parameters.R | N29: Medium-low
A30: Progression | B30: abx_prop | C30: Input assumption | D30: Parameters.R fixed list | E30: Proportion antibiotic-exposed | F30: 0.50 | G30: ='Baseline calculator'!$B$20 -> 0.373 | H30: proportion | I30: 0.25-0.50 | J30: Antibiotic prevalence in target ward/population | K30: Used in alpha multiplier | L30: England acute-care PPS estimate supports 0.373 as a central value; use higher values for elderly/high-risk wards. | M30: https://www.gov.uk/government/news/ukhsa-publishes-latest-survey-on-healthcare-associated-infections | N30: Medium-high
A31: Progression | B31: abx_mult | C31: Input assumption | D31: Parameters.R fixed list | E31: Multiplier for progression among antibiotic-exposed colonised patients | F31: 2.0 | G31: ='Baseline calculator'!$B$21 -> 2 | H31: multiplier | I31: 1.5-4.0 | J31: Antibiotic class/case-mix risk | K31: Used in alpha multiplier | L31: Keep as a sensitivity parameter because antibiotic class and patient risk vary substantially. | M31: https://scholars.houstonmethodist.org/en/publications/colonization-with-toxinogenic-c-difficile-upon-hospital-admission/; https://www.gov.uk/government/news/ukhsa-publishes-latest-survey-on-healthcare-associated-infections | N31: Low-medium
A32: Progression | B32: t_progress_C_to_I | C32: Input assumption | D32: Parameters.R fixed list | E32: Time window for progression calculation | F32: 5 | G32: ='Baseline calculator'!$B$22 -> 30 | H32: days | I32: 14-60 days | J32: Natural history / calibration window | K32: Used in alpha denominator | L32: A longer window is needed if prop_progress_C_to_I is interpreted as a cumulative risk rather than a daily proportion. | M32: https://scholars.houstonmethodist.org/en/publications/colonization-with-toxinogenic-c-difficile-upon-hospital-admission/; Uploaded Model1_ODE_Parameters.R | N32: Medium-low
A33: Progression | B33: alpha | C33: Calculated | D33: Parameters.R make_mod_parms() | E33: Daily C -> I progression rate | F33: 0.15/day with current fixed values | G33: ='Baseline calculator'!$B$47 -> 0.0029977167 | H33: per day | I33: 0.002-0.006/day for reported HO-CDI calibration | J33: prop_progress_C_to_I, abx_prop, abx_mult, t_progress_C_to_I | K33: alpha = prop_progress_C_to_I*((1-abx_prop)+(abx_prop*abx_mult))/t_progress_C_to_I | L33: Suggested inputs give alpha near 0.003/day; alpha*C0 is close to the daily HO-CDI target. | M33: https://www.gov.uk/government/statistics/mrsa-mssa-and-e-coli-bacteraemia-and-c-difficile-infection-annual-epidemiological-commentary/annual-epidemiological-commentary-gram-negative-mrsa-mssa-bacteraemia-and-c-difficile-infections-up-to-and-including-financial-year-2024-to-2025; https://scholars.houstonmethodist.org/en/publications/colonization-with-toxinogenic-c-difficile-upon-hospital-admission/; Uploaded Model1_ODE_Parameters.R | N33: Formula/calibration
A34: Decolonisation | B34: prop_decolonise_C_to_S | C34: Input assumption | D34: Parameters.R fixed list | E34: Proportion decolonising without treatment | F34: 0.05 | G34: ='Baseline calculator'!$B$23 -> 0.05 | H34: proportion | I34: 0.02-0.10 | J34: Model assumption / sensitivity | K34: mu = prop_decolonise_C_to_S / t_decolonise_C_to_S | L34: Weak evidence for a single acute-stay decolonisation value; keep and sensitivity-test. | M34: Uploaded Model1_ODE_Parameters.R | N34: Low
A35: Decolonisation | B35: t_decolonise_C_to_S | C35: Input assumption | D35: Parameters.R fixed list | E35: Mean time denominator for decolonisation | F35: 5 | G35: ='Baseline calculator'!$B$24 -> 5 | H35: days | I35: 5-30 | J35: Model assumption / sensitivity | K35: mu = prop_decolonise_C_to_S / t_decolonise_C_to_S | L35: Retain as modelling assumption unless you add a longer colonisation-duration structure. | M35: Uploaded Model1_ODE_Parameters.R | N35: Low
A36: Decolonisation | B36: mu | C36: Calculated | D36: Parameters.R make_mod_parms() | E36: Daily C -> S decolonisation rate | F36: 0.01/day | G36: ='Baseline calculator'!$B$48 -> 0.01 | H36: per day | I36: Depends on decolonisation inputs | J36: prop_decolonise_C_to_S, t_decolonise_C_to_S | K36: mu = prop_decolonise_C_to_S / t_decolonise_C_to_S | L36: Formula-derived; not a separate sourced parameter. | M36: Uploaded Model1_ODE_Parameters.R | N36: Formula
A37: LOS / discharge | B37: losS | C37: Input assumption | D37: Parameters.R fixed list | E37: Susceptible LOS denominator | F37: 7 | G37: ='Baseline calculator'!$B$25 -> 7 | H37: days | I37: 5-10 | J37: Effective overnight acute LOS | K37: disS = 1/(losS + t_patient_transfer) | L37: Compatible with a 7.5-day effective stay once 0.5-day transfer is included. | M37: https://www.health.org.uk/reports-and-analysis/briefings/longer-hospital-stays-and-fewer-admissions; https://www.england.nhs.uk/long-read/the-model-acute-pathway-standards-for-care-of-acutely-unwell-patients-in-their-first-72-hours-in-hospital/; Uploaded Model1_ODE_Parameters.R | N37: Medium
A38: LOS / discharge | B38: losC | C38: Input assumption | D38: Parameters.R fixed list | E38: Colonised LOS denominator | F38: 7 | G38: ='Baseline calculator'!$B$26 -> 7 | H38: days | I38: 5-10 | J38: Effective overnight acute LOS | K38: disC = 1/(losC + t_patient_transfer) | L38: Assume similar LOS to susceptible unless colonisation is a marker of frailty/case mix. | M38: https://www.health.org.uk/reports-and-analysis/briefings/longer-hospital-stays-and-fewer-admissions; Uploaded Model1_ODE_Parameters.R | N38: Medium-low
A39: LOS / discharge | B39: losI | C39: Input assumption | D39: Parameters.R fixed list | E39: Infected LOS denominator | F39: 14 | G39: ='Baseline calculator'!$B$27 -> 14 | H39: days | I39: 10-21 | J39: Symptomatic CDI/acute-care LOS | K39: disI = 1/(losI + t_patient_transfer) | L39: Infected patients have longer stays than non-infected patients in the model. | M39: https://www.nice.org.uk/guidance/ng199/chapter/Recommendations; Uploaded Model1_ODE_Parameters.R | N39: Medium-low
A40: LOS / discharge | B40: losFN | C40: Input assumption | D40: Parameters.R fixed list | E40: FN discharge denominator | F40: 14 | G40: ='Baseline calculator'!$B$28 -> 14 | H40: days | I40: 10-21 | J40: Symptomatic but not confirmed; retesting competing exit | K40: disFN = 1/(losFN + t_patient_transfer) | L40: Keep equal to losI unless modelling faster clinical reassessment. | M40: Uploaded Model1_ODE_Parameters.R | N40: Model assumption
...

Sheet Summary
A1: Item | B1: Value
A2: Workbook purpose | B2: Sourcing and consistency table for Model 1 ODE CDI parameters.
A3: Main addition | B3: Column C classifies each item as an input/scenario setting, calculated value, runtime calculated quantity, or helper target.
A4: Script location added | B4: Column D gives the script and section/function where each value is set or calculated.
A5: Dependencies added | B5: Column J lists the parameters that determine each calculated value.
A6: Consistency check | B6: The Baseline calculator sheet calculates derived suggested values from the same input assumptions; Parameter table column G links to those cells.
A7: Suggested model scale | B7: N0 = 1,000 occupied acute beds.
A8: Suggested admission rate | B8: adm_rate = N0 / 7.5 = 133.3 admissions/day.
A9: Primary calibration target | B9: Hospital-onset CDI = 23.3 per 100,000 bed-days = about 85/year per 1,000 occupied beds.
A10: Important caveat | B10: Betas and alpha are calibration parameters, not directly observable constants. Use annual confirmed HO-CDI and plausibility checks for colonisation flows.

Sheet Sources
A1: Source | B1: URL / file
A2: UKHSA annual epidemiological commentary FY2024/25 | B2: https://www.gov.uk/government/statistics/mrsa-mssa-and-e-coli-bacteraemia-and-c-difficile-infection-annual-epidemiological-commentary/annual-epidemiological-commentary-gram-negative-mrsa-mssa-bacteraemia-and-c-difficile-infections-up-to-and-including-financial-year-2024-to-2025
A3: NHS England bed availability and occupancy | B3: https://www.england.nhs.uk/statistics/statistical-work-areas/bed-availability-and-occupancy/
A4: Nuffield Trust hospital bed occupancy | B4: https://www.nuffieldtrust.org.uk/resource/hospital-bed-occupancy
A5: NHS Digital admitted patient care activity 2024/25 | B5: https://digital.nhs.uk/data-and-information/publications/statistical/hospital-admitted-patient-care-activity/2024-25
A6: Health Foundation length of stay analysis | B6: https://www.health.org.uk/reports-and-analysis/briefings/longer-hospital-stays-and-fewer-admissions
A7: NHS England Model Acute Pathway | B7: https://www.england.nhs.uk/long-read/the-model-acute-pathway-standards-for-care-of-acutely-unwell-patients-in-their-first-72-hours-in-hospital/
A8: Toxigenic C. difficile colonisation meta-analysis | B8: https://link.springer.com/article/10.1186/s13099-024-00674-0
A9: Colonisation with toxigenic C. difficile and risk of infection meta-analysis | B9: https://scholars.houstonmethodist.org/en/publications/colonization-with-toxinogenic-c-difficile-upon-hospital-admission/
A10: UKHSA 2023 PPS antibiotic use news summary | B10: https://www.gov.uk/government/news/ukhsa-publishes-latest-survey-on-healthcare-associated-infections
A11: UKHSA diagnostic test accuracy rapid review | B11: https://www.gov.uk/government/publications/clostridioides-difficile-diagnostic-test-accuracy
A12: Oxford University Hospitals C. difficile lab turnaround/retest | B12: https://www.ouh.nhs.uk/microbiology/a-z/c-difficile/
... A26: Health foundation drivers of increasing length of stay | B26: https://www.health.org.uk/reports-and-analysis/briefings/what-s-driving-increasing-length-of-stay-in-hospitals-since-2019
